Workbook

Sheet Overall performance  
A1: KỊCH BẢN 4M (tạm tính) => Cần breakdown theo tháng để có target follow và Actual tracking perf monthly => Góc overview
A3: Kịch bản 4M | B3: Jan | C3: Feb | D3: Mar | E3: Apr | F3: May | G3: Jun | H3: Jul | I3: Aug | J3: Sep | K3: Oct | L3: Nov | M3: Dec
A4: Total page views (traffic) | B4: =SUM(B7:B11) -> 0 | C4: =SUM(C7:C11) -> 0 | D4: =SUM(D7:D11) -> 0 | E4: =SUM(E7:E11) -> 0 | F4: =SUM(F7:F11) -> 0 | G4: =SUM(G7:G11) -> 0 | H4: =SUM(H7:H11) -> 0 | I4: =SUM(I7:I11) -> 0 | ... L4: =SUM(L7:L11) -> 0 | M4: 4000000
A5: Net add | C5: =C4-B4 -> 0 | D5: =D4-C4 -> 0 | E5: =E4-D4 -> 0 | F5: =F4-E4 -> 0 | G5: =G4-F4 -> 0 | H5: =H4-G4 -> 0 | I5: =I4-H4 -> 0 | J5: =J4-I4 -> 0 | ... L5: =L4-K4 -> 0
A6: % Growth Rate
A7: Organic
A8: Paids
A9: Direct
A10: Social
A11: Others
A12: Actual | B12: Jan | C12: Feb | D12: Mar | E12: Apr | F12: May | G12: Jun | H12: Jul | I12: Aug | J12: Sep | K12: Oct | L12: Nov | M12: Dec
A13: Total page views | B13: =SUM(B16:B20) -> 0 | C13: =SUM(C16:C20) -> 0 | D13: =SUM(D16:D20) -> 0 | E13: =SUM(E16:E20) -> 0 | F13: =SUM(F16:F20) -> 0 | G13: =SUM(G16:G20) -> 0 | H13: =SUM(H16:H20) -> 0
A14: Net add | C14: =C13-B13 -> 0 | D14: =D13-C13 -> 0 | E14: =E13-D13 -> 0 | F14: =F13-E13 -> 0 | G14: =G13-F13 -> 0 | H14: =H13-G13 -> 0
A15: % Growth Rate
A16: Organic
A17: Paids
A18: Direct
A19: Social
A20: Others

Sheet Details follow
A1: Góc view để so sánh và nhìn trend theo cùng kỳ và full month theo perf của từng nhóm để xem impact và perf
A3: Project Group | B3: Update to: | C3: 46048 | D3: 46054 | E3: 46082 | F3: 46113 | G3: 46143 | H3: 46174 | I3: 46204 | J3: 46235 | K3: Vs. SPLM | M3: Full month | N3: 46023 | O3: 46054 | P3: 46082 | Q3: 46113 | R3: 46143 | S3: 46174 | T3: 46204 | U3: Vs. LM
A4: Traffic (Page Views) | C4: =SUM(C7,C14,M14) -> 0 | D4: =SUM(D7,D14,N14) -> 0 | E4: =SUM(E7,E14,O14) -> 0 | F4: =SUM(F7,F14,P14) -> 0 | G4: =SUM(G7,G14,Q14) -> 0 | H4: =SUM(H7,H14,R14) -> 0 | I4: =SUM(I7,I14,S14) -> 0 | J4: =SUM(J7,J14,T14) -> 0 | K4: =SUM(K7,K14,U14) -> 0 | N4: =SUM(N7,N14,X14) -> 0 | O4: =SUM(O7,O14,Y14) -> 0 | P4: =SUM(P7,P14,Z14) -> 0 | Q4: =SUM(Q7,Q14,AA14) -> 0 | R4: =SUM(R7,R14,AB14) -> 0 | S4: =SUM(S7,S14,AC14) -> 0 | T4: =SUM(T7,T14,AD14) -> 0 | U4: =T4-S4 -> 0
A5: Net change | D5: =D4-C4 -> 0 | E5: =E4-D4 -> 0 | F5: =F4-E4 -> 0 | G5: =G4-F4 -> 0 | H5: =H4-G4 -> 0 | I5: =I4-H4 -> 0 | J5: =J4-I4 -> 0 | K5: =K4-J4 -> 0 | N5: =N4-M4 -> 0 | O5: =O4-N4 -> 0 | P5: =P4-O4 -> 0 | Q5: =Q4-P4 -> 0 | R5: =R4-Q4 -> 0 | S5: =S4-R4 -> 0 | T5: =T4-S4 -> 0 | U5: =T5-S5 -> 0
A6: Growth Rate (%) | D6: =D4/C4-1 -> #DIV/0! | E6: =E4/D4-1 -> #DIV/0! | F6: =F4/E4-1 -> #DIV/0! | G6: =G4/F4-1 -> #DIV/0! | H6: =H4/G4-1 -> #DIV/0! | I6: =I4/H4-1 -> #DIV/0! | J6: =J4/I4-1 -> #DIV/0! | K6: =K4/J4-1 -> #DIV/0! | N6: =N4/M4-1 -> #DIV/0! | O6: =O4/N4-1 -> #DIV/0! | P6: =P4/O4-1 -> #DIV/0! | Q6: =Q4/P4-1 -> #DIV/0! | R6: =R4/Q4-1 -> #DIV/0! | S6: =S4/R4-1 -> #DIV/0! | T6: =T4/S4-1 -> #DIV/0! | U6: =T6-S6 -> #DIV/0!
A7: Organic | C7: =SUM(C9,C11,C13) -> 0 | D7: =SUM(D9,D11,D13) -> 0 | E7: =SUM(E9,E11,E13) -> 0 | F7: =SUM(F9,F11,F13) -> 0 | G7: =SUM(G9,G11,G13) -> 0 | H7: =SUM(H9,H11,H13) -> 0 | I7: =SUM(I9,I11,I13) -> 0 | J7: =SUM(J9,J11,J13) -> 0 | K7: =SUM(K9,K11) -> 0 | N7: =SUM(N9,N11,N13) -> 0 | O7: =SUM(O9,O11,O13) -> 0 | P7: =SUM(P9,P11,P13) -> 0 | Q7: =SUM(Q9,Q11,Q13) -> 0 | R7: =SUM(R9,R11,R13) -> 0 | S7: =SUM(S9,S11,S13) -> 0 | T7: =SUM(T9,T11,T13) -> 0 | U7: =T7-S7 -> 0
A8: Net change | D8: =D7-C7 -> 0 | E8: =E7-D7 -> 0 | F8: =F7-E7 -> 0 | G8: =G7-F7 -> 0 | H8: =H7-G7 -> 0 | I8: =I7-H7 -> 0 | J8: =J7-I7 -> 0 | K8: =K7-J7 -> 0 | N8: =N7-M7 -> 0 | O8: =O7-N7 -> 0 | P8: =P7-O7 -> 0 | Q8: =Q7-P7 -> 0 | R8: =R7-Q7 -> 0 | S8: =S7-R7 -> 0 | T8: =T7-S7 -> 0 | U8: =T8-S8 -> 0
B9: SEO
B10: Net change | D10: =D9-C9 -> 0 | E10: =E9-D9 -> 0 | F10: =F9-E9 -> 0 | G10: =G9-F9 -> 0 | H10: =H9-G9 -> 0 | I10: =I9-H9 -> 0 | J10: =J9-I9 -> 0 | K10: =K9-J9 -> 0 | N10: =N9-M9 -> 0 | O10: =O9-N9 -> 0 | P10: =P9-O9 -> 0 | Q10: =Q9-P9 -> 0 | R10: =R9-Q9 -> 0 | S10: =S9-R9 -> 0 | T10: =T9-S9 -> 0 | U10: =T10-S10 -> 0
B11: Blog
B12: Net change | D12: =D11-C11 -> 0 | E12: =E11-D11 -> 0 | F12: =F11-E11 -> 0 | G12: =G11-F11 -> 0 | H12: =H11-G11 -> 0 | I12: =I11-H11 -> 0 | J12: =J11-I11 -> 0 | K12: =K11-J11 -> 0 | N12: =N11-M11 -> 0 | O12: =O11-N11 -> 0 | P12: =P11-O11 -> 0 | Q12: =Q11-P11 -> 0 | R12: =R11-Q11 -> 0 | S12: =S11-R11 -> 0 | T12: =T11-S11 -> 0 | U12: =T12-S12 -> 0
A14: Paid
A15: Net change | D15: =D14-C14 -> 0 | E15: =E14-D14 -> 0 | F15: =F14-E14 -> 0 | G15: =G14-F14 -> 0 | H15: =H14-G14 -> 0 | I15: =I14-H14 -> 0 | J15: =J14-I14 -> 0 | K15: =K14-J14 -> 0 | N15: =N14-M14 -> 0 | O15: =O14-N14 -> 0 | P15: =P14-O14 -> 0 | Q15: =Q14-P14 -> 0 | R15: =R14-Q14 -> 0 | S15: =S14-R14 -> 0 | T15: =T14-S14 -> 0 | U15: =T15-S15 -> 0
B17: …..... | D17: =D16-C16 -> 0 | E17: =E16-D16 -> 0 | F17: =F16-E16 -> 0 | G17: =G16-F16 -> 0 | H17: =H16-G16 -> 0 | I17: =I16-H16 -> 0 | J17: =J16-I16 -> 0 | K17: =K16-J16 -> 0 | N17: =N16-M16 -> 0 | O17: =O16-N16 -> 0 | P17: =P16-O16 -> 0 | Q17: =Q16-P16 -> 0 | R17: =R16-Q16 -> 0 | S17: =S16-R16 -> 0 | T17: =T16-S16 -> 0 | U17: =T17-S17 -> 0
D19: =D18-C18 -> 0 | E19: =E18-D18 -> 0 | F19: =F18-E18 -> 0 | G19: =G18-F18 -> 0 | H19: =H18-G18 -> 0 | I19: =I18-H18 -> 0 | J19: =J18-I18 -> 0 | K19: =K18-J18 -> 0 | N19: =N18-M18 -> 0 | O19: =O18-N18 -> 0 | P19: =P18-O18 -> 0 | Q19: =Q18-P18 -> 0 | R19: =R18-Q18 -> 0 | S19: =S18-R18 -> 0 | T19: =T18-S18 -> 0 | U19: =T19-S19 -> 0
D21: =D20-C20 -> 0 | E21: =E20-D20 -> 0 | F21: =F20-E20 -> 0 | G21: =G20-F20 -> 0 | H21: =H20-G20 -> 0 | I21: =I20-H20 -> 0 | J21: =J20-I20 -> 0 | K21: =K20-J20 -> 0 | N21: =N20-M20 -> 0 | O21: =O20-N20 -> 0 | P21: =P20-O20 -> 0 | Q21: =Q20-P20 -> 0 | R21: =R20-Q20 -> 0 | S21: =S20-R20 -> 0 | T21: =T20-S20 -> 0 | U21: =T21-S21 -> 0
D23: =D22-C22 -> 0 | E23: =E22-D22 -> 0 | F23: =F22-E22 -> 0 | G23: =G22-F22 -> 0 | H23: =H22-G22 -> 0 | I23: =I22-H22 -> 0 | J23: =J22-I22 -> 0 | K23: =K22-J22 -> 0 | N23: =N22-M22 -> 0 | O23: =O22-N22 -> 0 | P23: =P22-O22 -> 0 | Q23: =Q22-P22 -> 0 | R23: =R22-Q22 -> 0 | S23: =S22-R22 -> 0 | T23: =T22-S22 -> 0 | U23: =T23-S23 -> 0
D25: =D24-C24 -> 0 | E25: =E24-D24 -> 0 | F25: =F24-E24 -> 0 | G25: =G24-F24 -> 0 | H25: =H24-G24 -> 0 | I25: =I24-H24 -> 0 | J25: =J24-I24 -> 0 | K25: =K24-J24 -> 0 | N25: =N24-M24 -> 0 | O25: =O24-N24 -> 0 | P25: =P24-O24 -> 0 | Q25: =Q24-P24 -> 0 | R25: =R24-Q24 -> 0 | S25: =S24-R24 -> 0 | T25: =T24-S24 -> 0 | U25: =T25-S25 -> 0
A26: …..
A27: Net change | D27: =D26-C26 -> 0 | E27: =E26-D26 -> 0 | F27: =F26-E26 -> 0 | G27: =G26-F26 -> 0 | H27: =H26-G26 -> 0 | I27: =I26-H26 -> 0 | J27: =J26-I26 -> 0 | K27: =K26-J26 -> 0 | N27: =N26-M26 -> 0 | O27: =O26-N26 -> 0 | P27: =P26-O26 -> 0 | Q27: =Q26-P26 -> 0 | R27: =R26-Q26 -> 0 | S27: =S26-R26 -> 0 | T27: =T26-S26 -> 0 | U27: =T27-S27 -> 0

Sheet Overall Performance
A1: UTD 23/08/2026 | B1: Full Month | O1: Month to Date
A2: Target | B2: 46023 | C2: 46054 | D2: 46082 | E2: 46113 | F2: 46143 | G2: 46174 | H2: 46204 | I2: 46235 | J2: 46266 | K2: 46296 | L2: 46327 | M2: 46357
A3: Total page views (traffic) | B3: 2601280 | C3: 3470470 | D3: 3221705 | E3: 2699883 | F3: =sum(F6:F11) -> 3272867 | G3: =sum(G6:G11) -> 3407958 | H3: =sum(H6:H11) -> 3167821 | I3: =sum(I6:I11) -> 3359168 | J3: 3509044 | K3: 3665607 | L3: 3829155 | M3: 4000000
A4: Net add | C4: =C3-B3 -> 869190 | D4: =D3-C3 -> -248765 | E4: =E3-D3 -> -521822 | F4: =F3-E3 -> 572984 | G4: =G3-F3 -> 135091 | H4: =H3-G3 -> -240137 | I4: =I3-H3 -> 191347 | J4: =J3-I3 -> 149876 | ... M4: =M3-L3 -> 170845
A5: % Growth Rate | C5: =IFERROR((C3/B3)-1, 0) -> 0.33413935 | D5: =IFERROR((D3/C3)-1, 0) -> -0.071680493 | E5: =IFERROR((E3/D3)-1, 0) -> -0.16197076 | G5: =IFERROR((G3/F3)-1, 0) -> 0.041276043 | H5: =IFERROR((H3/G3)-1, 0) -> -0.070463603 | I5: =IFERROR((I3/H3)-1, 0) -> 0.06040335 | J5: =IFERROR((J3/I3)-1, 0) -> 0.044617 | K5: =IFERROR((K3/J3)-1, 0) -> 0.044616995 | L5: =IFERROR((L3/K3)-1, 0) -> 0.044616894 | M5: =IFERROR((M3/L3)-1, 0) -> 0.044616893
A6: Organic | F6: 1669075 | G6: 1648550 | H6: 1875191 | I6: 1684831.7
A7: Paid | F7: 703135 | G7: 967001 | H7: 491874 | I7: 612341.99
A8: Direct | F8: 637005 | G8: 488574 | H8: 440855 | I8: 676162.64
A9: Cross | F9: 17748 | G9: 15488 | H9: 6084 | I9: 21975.667
A10: Referral | F10: 201169 | G10: 255127 | H10: 329659 | I10: 340393.45
A11: Others | F11: 44735 | G11: 33218 | H11: 24158 | I11: 23462.535
A13: Actual | B13: 46023 | C13: 46054 | D13: 46082 | E13: 46113 | F13: 46143 | G13: 46174 | H13: 46204 | I13: 46257 | J13: 46266 | K13: 46296 | L13: 46327 | M13: 46357 | O13: 46143 | P13: 46174 | Q13: 46204 | R13: 46235 | S13: 46266 | T13: 46296 | U13: 46327 | V13: 46357
A14: Total page views (traffic) | B14: 2601280 | C14: 3470470 | D14: 3221705 | E14: 2699883 | F14: =sum(F18:F23) -> 3272867 | G14: =sum(G18:G23) -> 3407958 | H14: =sum(H18:H23) -> 3167821 | I14: =sum(I18:I23) -> 2489454 | J14: =sum(J18:J23) -> 0 | K14: =sum(K18:K23) -> 0 | L14: =sum(L18:L23) -> 0 | M14: =sum(M18:M23) -> 0 | O14: =sum(O18:O23) -> 2318673 | P14: =sum(P18:P23) -> 2682897 | Q14: =sum(Q18:Q23) -> 2177329 | R14: =sum(R18:R23) -> 2489454 | S14: =sum(S18:S23) -> 0 | T14: =sum(T18:T23) -> 0 | U14: =sum(U18:U23) -> 0 | V14: =sum(V18:V23) -> 0
A15: Net add | C15: =C14-B14 -> 869190 | D15: =D14-C14 -> -248765 | E15: =E14-D14 -> -521822 | F15: =F14-E14 -> 572984 | G15: =G14-F14 -> 135091 | H15: =H14-G14 -> -240137 | I15: =I14-H14 -> -678367 | J15: =J14-I14 -> -2489454 | ... M15: =M14-L14 -> 0 | P15: =P14-O14 -> 364224 | Q15: =Q14-P14 -> -505568 | R15: =R14-Q14 -> 312125
A16: % Growth Rate | C16: =IFERROR((C14/B14)-1, 0) -> 0.33413935 | D16: =IFERROR((D14/C14)-1, 0) -> -0.071680493 | E16: =IFERROR((E14/D14)-1, 0) -> -0.16197076 | G16: =IFERROR((G14/F14)-1, 0) -> 0.041276043 | H16: =IFERROR((H14/G14)-1, 0) -> -0.070463603 | I16: =IFERROR((I14/H14)-1, 0) -> -0.2141431 | J16: =IFERROR((J14/I14)-1, 0) -> -1 | K16: =IFERROR((K14/J14)-1, 0) -> 0 | L16: =IFERROR((L14/K14)-1, 0) -> 0 | M16: =IFERROR((M14/L14)-1, 0) -> 0 | P16: =(P14/O14)-1 -> 0.15708295 | Q16: =(Q14/P14)-1 -> -0.18844108 | R16: =(R14/Q14)-1 -> 0.14335224
A17: % Target Rate | F17: =F14/F3 -> 1 | G17: =G14/G3 -> 1 | H17: =H14/H3 -> 1 | I17: =I14/I3 -> 0.74109244 | J17: =J14/J3 -> 0 | K17: =K14/K3 -> 0 | L17: =L14/L3 -> 0 | M17: =M14/M3 -> 0
A18: Organic | F18: ='Source Detail Flow'!G6 -> 1669075 | G18: ='Source Detail Flow'!H6 -> 1648550 | H18: ='Source Detail Flow'!I6 -> 1875191 | I18: ='Source Detail Flow'!J6 -> 1248616 | O18: ='Source Detail Flow'!R6 -> 1253336 | P18: ='Source Detail Flow'!S6 -> 1267036 | Q18: ='Source Detail Flow'!T6 -> 1408084 | R18: ='Source Detail Flow'!U6 -> 1248616
A19: Paid | F19: ='Source Detail Flow'!G15 -> 703135 | G19: ='Source Detail Flow'!H15 -> 967001 | H19: ='Source Detail Flow'!I15 -> 491874 | I19: ='Source Detail Flow'!J15 -> 453802 | O19: ='Source Detail Flow'!R15 -> 376786 | P19: ='Source Detail Flow'!S15 -> 798331 | Q19: ='Source Detail Flow'!T15 -> 171834 | R19: ='Source Detail Flow'!U15 -> 453802
A20: Direct | F20: ='Source Detail Flow'!G24 -> 637005 | G20: ='Source Detail Flow'!H24 -> 488574 | H20: ='Source Detail Flow'!I24 -> 440855 | I20: ='Source Detail Flow'!J24 -> 501099 | O20: ='Source Detail Flow'!R24 -> 489902 | P20: ='Source Detail Flow'!S24 -> 374413 | Q20: ='Source Detail Flow'!T24 -> 339018 | R20: ='Source Detail Flow'!U24 -> 501099
A21: Cross | F21: ='Source Detail Flow'!G33 -> 17748 | G21: ='Source Detail Flow'!H33 -> 15488 | H21: ='Source Detail Flow'!I33 -> 6084 | I21: ='Source Detail Flow'!J33 -> 16286 | O21: ='Source Detail Flow'!R33 -> 7846 | P21: ='Source Detail Flow'!S33 -> 12889 | Q21: ='Source Detail Flow'!T33 -> 2009 | R21: ='Source Detail Flow'!U33 -> 16286
A22: Referral | F22: ='Source Detail Flow'!G42 -> 201169 | G22: ='Source Detail Flow'!H42 -> 255127 | H22: ='Source Detail Flow'!I42 -> 329659 | I22: ='Source Detail Flow'!J42 -> 252319 | O22: ='Source Detail Flow'!R42 -> 155424 | P22: ='Source Detail Flow'!S42 -> 204749 | Q22: ='Source Detail Flow'!T42 -> 239886 | R22: ='Source Detail Flow'!U42 -> 252319
A23: Others | F23: ='Source Detail Flow'!G51 -> 44735 | G23: ='Source Detail Flow'!H51 -> 33218 | H23: ='Source Detail Flow'!I51 -> 24158 | I23: ='Source Detail Flow'!J51 -> 17332 | O23: ='Source Detail Flow'!R51 -> 35379 | P23: ='Source Detail Flow'!S51 -> 25479 | Q23: ='Source Detail Flow'!T51 -> 16498 | R23: ='Source Detail Flow'!U51 -> 17332
A25: %Organic | F25: =F18/$F$14 -> 0.50997337 | G25: =G18/$G$14 -> 0.48373542 | H25: =H18/$H$14 -> 0.5919498 | I25: =I18/$I$14 -> 0.50156219 | O25: =O18/$O$14 -> 0.54054021 | P25: =P18/$P$14 -> 0.47226412 | Q25: =Q18/$Q$14 -> 0.64670245 | R25: =R18/$R$14 -> 0.50156219
A26: %Paid | F26: =F19/$F$14 -> 0.21483763 | G26: =G19/$G$14 -> 0.28374792 | H26: =H19/$H$14 -> 0.15527203 | I26: =I19/$I$14 -> 0.18228977 | O26: =O19/$O$14 -> 0.16250071 | P26: =P19/$P$14 -> 0.29756304 | Q26: =Q19/$Q$14 -> 0.07891963 | R26: =R19/$R$14 -> 0.18228977
A27: %Direct | F27: =F20/$F$14 -> 0.19463211 | G27: =G20/$G$14 -> 0.14336268 | H27: =H20/$H$14 -> 0.13916664 | I27: =I20/$I$14 -> 0.20128872 | O27: =O20/$O$14 -> 0.21128551 | P27: =P20/$P$14 -> 0.13955549 | Q27: =Q20/$Q$14 -> 0.15570362 | R27: =R20/$R$14 -> 0.20128872
A28: %Cross | F28: =F21/$F$14 -> 0.0054227685 | G28: =G21/$G$14 -> 0.0045446569 | H28: =H21/$H$14 -> 0.0019205631 | I28: =I21/$I$14 -> 0.0065419968 | O28: =O21/$O$14 -> 0.003383832 | P28: =P21/$P$14 -> 0.0048041352 | Q28: =Q21/$Q$14 -> 0.00092269014 | R28: =R21/$R$14 -> 0.0065419968
A29: %Referral | F29: =F22/$F$14 -> 0.061465681 | G29: =G22/$G$14 -> 0.074862132 | H29: =H22/$H$14 -> 0.10406491 | I29: =I22/$I$14 -> 0.10135516 | O29: =O22/$O$14 -> 0.067031444 | P29: =P22/$P$14 -> 0.076316385 | Q29: =Q22/$Q$14 -> 0.11017444 | R29: =R22/$R$14 -> 0.10135516
A30: %Others | F30: =F23/$F$14 -> 0.013668444 | G30: =G23/$G$14 -> 0.0097471859 | H30: =H23/$H$14 -> 0.0076260622 | I30: =I23/$I$14 -> 0.0069621692 | O30: =O23/$O$14 -> 0.015258296 | P30: =P23/$P$14 -> 0.0094968238 | Q30: =Q23/$Q$14 -> 0.0075771737 | R30: =R23/$R$14 -> 0.0069621692
A40: Notes
A41: Organic
A42: Organic Search: Người dùng tìm kiếm từ khóa trên Google / Cốc Cốc và bấm vào kết quả hiển thị tự nhiên
A43: Paid
A44: Paid Other: Lưu lượng từ các chiến dịch quảng cáo trả phí khác (quảng cáo đối tác liên kết, tài trợ Affiliate).
A45: Paid Search: Người dùng tìm kiếm trên Google và bấm vào kết quả quảng cáo tìm kiếm trả tiền (Google Search Ads).
A46: Paid Social: Khách bấm vào các bài viết / video chạy quảng cáo trả tiền trên Facebook Ads, TikTok Ads.
A47: Referral
A48: Referral Domain: Lượng truy cập từ người dùng bấm vào link momo.vn đặt trên các website bên ngoài (bài báo PR VnExpress/CafeF, website đối tác ngân hàng/rạp phim, diễn đàn).
A49: AI Referrals: Người dùng hỏi các công cụ AI (ChatGPT, Perplexity, Claude, Gemini) và bấm vào đường link trích dẫn nguồn momo.vn.
A50: App Referral: Người dùng đang mở các ứng dụng trên điện thoại (đặc biệt là App MoMo, Zalo, Gmail) bấm link mở trang web momo.vn.
A51: Direct
...

Sheet Source Detail Flow
A1: Project Group | B1: Update to: | C1: 46048 | D1: 46054 | E1: 46082 | F1: 46113 | G1: 46143 | H1: 46174 | I1: 46204 | J1: 46235 | K1: Vs. LM | M1: Full month | N1: 46023 | O1: 46054 | P1: 46082 | Q1: 46113 | R1: 46143 | S1: 46174 | T1: 46204 | U1: 46235 | V1: Vs. SPLM
A2: Traffic (Page Views) | C2: =SUM(C6,C15,M15) -> 0 | D2: =SUM(D6,D15,N15) -> 0 | E2: =SUM(E6,E15,O15) -> 0 | F2: =SUM(F6,F15,P15) -> 0 | G2: =SUM(G6,G15,G24,G33,G42,G51) -> 3272867 | H2: =SUM(H6,H15,H24,H33,H42,H51) -> 3407958 | I2: =SUM(I6,I15,I24,I33,I42,I51) -> 3167821 | J2: =SUM(J6,J15,J24,J33,J42,J51) -> 2489454 | K2: =J2-I2 -> -678367 | N2: 2601280 | O2: 3470470 | P2: 3221705 | Q2: 2699883 | R2: =SUM(R6,R15,R24,R33,R42,R51) -> 2318673 | S2: =SUM(S6,S15,S24,S33,S42,S51) -> 2682897 | T2: =SUM(T6,T15,T24,T33,T42,T51) -> 2177329 | U2: =SUM(U6,U15,U24,U33,U42,U51) -> 2489454 | V2: =U2-T2 -> 312125
A3: Net change | D3: =D2-C2 -> 0 | E3: =E2-D2 -> 0 | F3: =F2-E2 -> 0 | G3: =G2-F2 -> 3272867 | H3: =H2-G2 -> 135091 | I3: =I2-H2 -> -240137 | J3: =J2-I2 -> -678367 | N3: =N2-M2 -> 2601280 | O3: =O2-N2 -> 869190 | P3: =P2-O2 -> -248765 | Q3: =Q2-P2 -> -521822 | R3: =R2-Q2 -> -381210 | S3: =S2-R2 -> 364224 | T3: =T2-S2 -> -505568 | U3: =U2-T2 -> 312125
A4: Growth Rate (%) | D4: =IFERROR(D2/C2-1,0) -> 0 | E4: =IFERROR(E2/D2-1,0) -> 0 | F4: =IFERROR(F2/E2-1,0) -> 0 | G4: =IFERROR(G2/F2-1,0) -> 0 | H4: =IFERROR(H2/G2-1,0) -> 0.041276043 | I4: =IFERROR(I2/H2-1,0) -> -0.070463603 | J4: =IFERROR(J2/I2-1,0) -> -0.2141431 | K4: =J4-I4 -> -0.14367949 | O4: =O2/N2-1 -> 0.33413935 | P4: =P2/O2-1 -> -0.071680493 | Q4: =Q2/P2-1 -> -0.16197076 | R4: =R2/Q2-1 -> -0.14119501 | S4: =S2/R2-1 -> 0.15708295 | T4: =T2/S2-1 -> -0.18844108 | U4: =U2/T2-1 -> 0.14335224 | V4: =U4-T4 -> 0.33179332
A6: Organic | C6: =SUM(C8,C10,C12) -> 0 | D6: =SUM(D8,D10,D12) -> 0 | E6: =SUM(E8,E10,E12) -> 0 | F6: =SUM(F8,F10,F12) -> 0 | G6: =SUM(G8,G10,G12) -> 1669075 | H6: =SUM(H8,H10,H12) -> 1648550 | I6: =SUM(I8,I10,I12) -> 1875191 | J6: =SUM(J8,J10,J12) -> 1248616 | K6: =J6-I6 -> -626575 | N6: =SUM(N8,N10,N14) -> 0 | O6: =SUM(O8,O10,O14) -> 0 | P6: =SUM(P8,P10,P14) -> 0 | Q6: =SUM(Q8,Q10,Q14) -> 0 | R6: =SUM(R8,R10,R12) -> 1253336 | S6: =SUM(S8,S10,S12) -> 1267036 | T6: =SUM(T8,T10,T12) -> 1408084 | U6: =SUM(U8,U10,U12) -> 1248616 | V6: =U6-T6 -> -159468
A7: Net change | D7: =D6-C6 -> 0 | E7: =E6-D6 -> 0 | F7: =F6-E6 -> 0 | G7: =G6-F6 -> 1669075 | H7: =H6-G6 -> -20525 | I7: =I6-H6 -> 226641 | J7: =J6-I6 -> -626575 | N7: =N6-M6 -> 0 | O7: =O6-N6 -> 0 | P7: =P6-O6 -> 0 | Q7: =Q6-P6 -> 0 | R7: =R6-Q6 -> 1253336 | S7: =S6-R6 -> 13700 | T7: =T6-S6 -> 141048 | U7: =U6-T6 -> -159468
B8: Cinema Hub | G8: 726916 | H8: 725084 | I8: 722336 | J8: 495785 | K8: =J8-I8 -> -226551 | R8: 539857 | S8: 562200 | T8: 538955 | U8: 495785 | V8: =U8-T8 -> -43170
B9: Net change | D9: =D8-C8 -> 0 | E9: =E8-D8 -> 0 | F9: =F8-E8 -> 0 | G9: =G8-F8 -> 726916 | H9: =H8-G8 -> -1832 | I9: =I8-H8 -> -2748 | J9: =J8-I8 -> -226551 | N9: =N8-M8 -> 0 | O9: =O8-N8 -> 0 | P9: =P8-O8 -> 0 | Q9: =Q8-P8 -> 0 | R9: =R8-Q8 -> 539857 | S9: =S8-R8 -> 22343 | T9: =T8-S8 -> -23245 | U9: =U8-T8 -> -43170
B10: Financial Hub | G10: 49109 | H10: 48429 | I10: 66359 | J10: 44742 | K10: =J10-I10 -> -21617 | R10: 36900 | S10: 35802 | T10: 51362 | U10: 44742 | V10: =U10-T10 -> -6620
B11: Net change | D11: =D10-C10 -> 0 | E11: =E10-D10 -> 0 | F11: =F10-E10 -> 0 | G11: =G10-F10 -> 49109 | H11: =H10-G10 -> -680 | I11: =I10-H10 -> 17930 | J11: =J10-I10 -> -21617 | N11: =N10-M10 -> 0 | O11: =O10-N10 -> 0 | P11: =P10-O10 -> 0 | Q11: =Q10-P10 -> 0 | R11: =R10-Q10 -> 36900 | S11: =S10-R10 -> -1098 | T11: =T10-S10 -> 15560 | U11: =U10-T10 -> -6620
B12: Others | G12: 893050 | H12: 875037 | I12: 1086496 | J12: 708089 | K12: =J12-I12 -> -378407 | R12: 676579 | S12: 669034 | T12: 817767 | U12: 708089 | V12: =U12-T12 -> -109678
B13: Net change | D13: =D12-C12 -> 0 | E13: =E12-D12 -> 0 | F13: =F12-E12 -> 0 | G13: =G12-F12 -> 893050 | H13: =H12-G12 -> -18013 | I13: =I12-H12 -> 211459 | J13: =J12-I12 -> -378407 | R13: =R12-Q12 -> 676579 | S13: =S12-R12 -> -7545 | T13: =T12-S12 -> 148733 | U13: =U12-T12 -> -109678
A15: Paid | C15: =SUM(C17,C19,C21) -> 0 | D15: =SUM(D17,D19,D21) -> 0 | E15: =SUM(E17,E19,E21) -> 0 | F15: =SUM(F17,F19,F21) -> 0 | G15: =SUM(G17,G19,G21) -> 703135 | H15: =SUM(H17,H19,H21) -> 967001 | I15: =SUM(I17,I19,I21) -> 491874 | J15: =SUM(J17,J19,J21) -> 453802 | K15: =J15-I15 -> -38072 | R15: =SUM(R17,R19,R21) -> 376786 | S15: =SUM(S17,S19,S21) -> 798331 | T15: =SUM(T17,T19,T21) -> 171834 | U15: =SUM(U17,U19,U21) -> 453802 | V15: =U15-T15 -> 281968
A16: Net change | D16: =D15-C15 -> 0 | E16: =E15-D15 -> 0 | F16: =F15-E15 -> 0 | G16: =G15-F15 -> 703135 | H16: =H15-G15 -> 263866 | I16: =I15-H15 -> -475127 | J16: =J15-I15 -> -38072 | N16: =N15-M15 -> 0 | O16: =O15-N15 -> 0 | P16: =P15-O15 -> 0 | Q16: =Q15-P15 -> 0 | R16: =R15-Q15 -> 376786 | S16: =S15-R15 -> 421545 | T16: =T15-S15 -> -626497 | U16: =U15-T15 -> 281968
B17: Cinema Hub | G17: 1425 | H17: 24582 | I17: 6056 | J17: 14162 | K17: =J17-I17 -> 8106 | R17: 958 | S17: 24431 | T17: 2120 | U17: 14162 | V17: =U17-T17 -> 12042
B18: Net change | D18: =D17-C17 -> 0 | E18: =E17-D17 -> 0 | F18: =F17-E17 -> 0 | G18: =G17-F17 -> 1425 | H18: =H17-G17 -> 23157 | I18: =I17-H17 -> -18526 | J18: =J17-I17 -> 8106 | N18: =N17-M17 -> 0 | O18: =O17-N17 -> 0 | P18: =P17-O17 -> 0 | Q18: =Q17-P17 -> 0 | R18: =R17-Q17 -> 958 | S18: =S17-R17 -> 23473 | T18: =T17-S17 -> -22311 | U18: =U17-T17 -> 12042
B19: Financial Hub | G19: 91258 | H19: 69033 | I19: 31835 | J19: 57140 | K19: =J19-I19 -> 25305 | R19: 67814 | S19: 52745 | T19: 14695 | U19: 57140 | V19: =U19-T19 -> 42445
B20: Net change | D20: =D19-C19 -> 0 | E20: =E19-D19 -> 0 | F20: =F19-E19 -> 0 | G20: =G19-F19 -> 91258 | H20: =H19-G19 -> -22225 | I20: =I19-H19 -> -37198 | J20: =J19-I19 -> 25305 | N20: =N19-M19 -> 0 | O20: =O19-N19 -> 0 | P20: =P19-O19 -> 0 | Q20: =Q19-P19 -> 0 | R20: =R19-Q19 -> 67814 | S20: =S19-R19 -> -15069 | T20: =T19-S19 -> -38050 | U20: =U19-T19 -> 42445
B21: Others | G21: 610452 | H21: 873386 | I21: 453983 | J21: 382500 | K21: =J21-I21 -> -71483 | R21: 308014 | S21: 721155 | T21: 155019 | U21: 382500 | V21: =U21-T21 -> 227481
B22: Net change | D22: =D21-C21 -> 0 | E22: =E21-D21 -> 0 | F22: =F21-E21 -> 0 | G22: =G21-F21 -> 610452 | H22: =H21-G21 -> 262934 | I22: =I21-H21 -> -419403 | J22: =J21-I21 -> -71483 | R22: =R21-Q21 -> 308014 | S22: =S21-R21 -> 413141 | T22: =T21-S21 -> -566136 | U22: =U21-T21 -> 227481
A24: Direct | C24: =SUM(C26,C28,C30) -> 0 | D24: =SUM(D26,D28,D30) -> 0 | E24: =SUM(E26,E28,E30) -> 0 | F24: =SUM(F26,F28,F30) -> 0 | G24: =SUM(G26,G28,G30) -> 637005 | H24: =SUM(H26,H28,H30) -> 488574 | I24: =SUM(I26,I28,I30) -> 440855 | J24: =SUM(J26,J28,J30) -> 501099 | K24: =J24-I24 -> 60244 | N24: =N23-M23 -> 0 | O24: =O23-N23 -> 0 | P24: =P23-O23 -> 0 | Q24: =Q23-P23 -> 0 | R24: =SUM(R26,R28,R30) -> 489902 | S24: =SUM(S26,S28,S30) -> 374413 | T24: =SUM(T26,T28,T30) -> 339018 | U24: =SUM(U26,U28,U30) -> 501099 | V24: =U24-T24 -> 162081
A25: Net change | D25: =D24-C24 -> 0 | E25: =E24-D24 -> 0 | F25: =F24-E24 -> 0 | G25: =G24-F24 -> 637005 | H25: =H24-G24 -> -148431 | I25: =I24-H24 -> -47719 | J25: =J24-I24 -> 60244 | R25: =R24-Q24 -> 489902 | S25: =S24-R24 -> -115489 | T25: =T24-S24 -> -35395 | U25: =U24-T24 -> 162081
B26: Cinema Hub | G26: 215661 | H26: 64908 | I26: 62105 | J26: 39180 | K26: =J26-I26 -> -22925 | N26: =N25-M25 -> 0 | O26: =O25-N25 -> 0 | P26: =P25-O25 -> 0 | Q26: =Q25-P25 -> 0 | R26: 187645 | S26: 46728 | T26: 48994 | U26: 39180 | V26: =U26-T26 -> -9814
B27: Net change | D27: =D26-C26 -> 0 | E27: =E26-D26 -> 0 | F27: =F26-E26 -> 0 | G27: =G26-F26 -> 215661 | H27: =H26-G26 -> -150753 | I27: =I26-H26 -> -2803 | J27: =J26-I26 -> -22925 | R27: =R26-Q26 -> 187645 | S27: =S26-R26 -> -140917 | T27: =T26-S26 -> 2266 | U27: =U26-T26 -> -9814
B28: Financial Hub | G28: 3856 | H28: 4248 | I28: 4712 | J28: 4928 | K28: =J28-I28 -> 216 | N28: =N27-M27 -> 0 | O28: =O27-N27 -> 0 | P28: =P27-O27 -> 0 | Q28: =Q27-P27 -> 0 | R28: 2928 | S28: 3259 | T28: 3164 | U28: 4928 | V28: =U28-T28 -> 1764
B29: Net change | D29: =D28-C28 -> 0 | E29: =E28-D28 -> 0 | F29: =F28-E28 -> 0 | G29: =G28-F28 -> 3856 | H29: =H28-G28 -> 392 | I29: =I28-H28 -> 464 | J29: =J28-I28 -> 216 | R29: =R28-Q28 -> 2928 | S29: =S28-R28 -> 331 | T29: =T28-S28 -> -95 | U29: =U28-T28 -> 1764
B30: Others | G30: 417488 | H30: 419418 | I30: 374038 | J30: 456991 | K30: =J30-I30 -> 82953 | R30: 299329 | S30: 324426 | T30: 286860 | U30: 456991 | V30: =U30-T30 -> 170131
B31: Net change | D31: =D30-C30 -> 0 | E31: =E30-D30 -> 0 | F31: =F30-E30 -> 0 | G31: =G30-F30 -> 417488 | H31: =H30-G30 -> 1930 | I31: =I30-H30 -> -45380 | J31: =J30-I30 -> 82953 | R31: =R30-Q30 -> 299329 | S31: =S30-R30 -> 25097 | T31: =T30-S30 -> -37566 | U31: =U30-T30 -> 170131
A33: Cross | C33: =SUM(C35,C37,C39) -> 0 | D33: =SUM(D35,D37,D39) -> 0 | E33: =SUM(E35,E37,E39) -> 0 | F33: =SUM(F35,F37,F39) -> 0 | G33: =SUM(G35,G37,G39) -> 17748 | H33: =SUM(H35,H37,H39) -> 15488 | I33: =SUM(I35,I37,I39) -> 6084 | J33: =SUM(J35,J37,J39) -> 16286 | K33: =J33-I33 -> 10202 | R33: =SUM(R35,R37,R39) -> 7846 | S33: =SUM(S35,S37,S39) -> 12889 | T33: =SUM(T35,T37,T39) -> 2009 | U33: =SUM(U35,U37,U39) -> 16286 | V33: =U33-T33 -> 14277
A34: Net change | D34: =D33-C33 -> 0 | E34: =E33-D33 -> 0 | F34: =F33-E33 -> 0 | G34: =G33-F33 -> 17748 | H34: =H33-G33 -> -2260 | I34: =I33-H33 -> -9404 | J34: =J33-I33 -> 10202 | R34: =R33-Q33 -> 7846 | S34: =S33-R33 -> 5043 | T34: =T33-S33 -> -10880 | U34: =U33-T33 -> 14277
B35: Cinema Hub | G35: 2 | H35: 5 | I35: 183 | J35: 827 | K35: =J35-I35 -> 644 | U35: 827 | V35: =U35-T35 -> 827
B36: Net change | D36: =D35-C35 -> 0 | E36: =E35-D35 -> 0 | F36: =F35-E35 -> 0 | G36: =G35-F35 -> 2 | H36: =H35-G35 -> 3 | I36: =I35-H35 -> 178 | J36: =J35-I35 -> 644 | R36: =R35-Q35 -> 0 | S36: =S35-R35 -> 0 | T36: =T35-S35 -> 0 | U36: =U35-T35 -> 827
B37: Financial Hub | G37: 1542 | H37: 1193 | I37: 851 | J37: 1315 | K37: =J37-I37 -> 464 | R37: 1189 | S37: 868 | T37: 437 | U37: 1315 | V37: =U37-T37 -> 878
B38: Net change | D38: =D37-C37 -> 0 | E38: =E37-D37 -> 0 | F38: =F37-E37 -> 0 | G38: =G37-F37 -> 1542 | H38: =H37-G37 -> -349 | I38: =I37-H37 -> -342 | J38: =J37-I37 -> 464 | R38: =R37-Q37 -> 1189 | S38: =S37-R37 -> -321 | T38: =T37-S37 -> -431 | U38: =U37-T37 -> 878
B39: Others | G39: 16204 | H39: 14290 | I39: 5050 | J39: 14144 | K39: =J39-I39 -> 9094 | R39: 6657 | S39: 12021 | T39: 1572 | U39: 14144 | V39: =U39-T39 -> 12572
B40: Net change | D40: =D39-C39 -> 0 | E40: =E39-D39 -> 0 | F40: =F39-E39 -> 0 | G40: =G39-F39 -> 16204 | H40: =H39-G39 -> -1914 | I40: =I39-H39 -> -9240 | J40: =J39-I39 -> 9094 | R40: =R39-Q39 -> 6657 | S40: =S39-R39 -> 5364 | T40: =T39-S39 -> -10449 | U40: =U39-T39 -> 12572
A42: Referral | C42: =SUM(C44,C46,C48) -> 0 | D42: =SUM(D44,D46,D48) -> 0 | E42: =SUM(E44,E46,E48) -> 0 | F42: =SUM(F44,F46,F48) -> 0 | G42: =SUM(G44,G46,G48) -> 201169 | H42: =SUM(H44,H46,H48) -> 255127 | I42: =SUM(I44,I46,I48) -> 329659 | J42: =SUM(J44,J46,J48) -> 252319 | K42: =J42-I42 -> -77340 | R42: =SUM(R44,R46,R48) -> 155424 | S42: =SUM(S44,S46,S48) -> 204749 | T42: =SUM(T44,T46,T48) -> 239886 | U42: =SUM(U44,U46,U48) -> 252319 | V42: =U42-T42 -> 12433
A43: Net change | D43: =D42-C42 -> 0 | E43: =E42-D42 -> 0 | F43: =F42-E42 -> 0 | G43: =G42-F42 -> 201169 | H43: =H42-G42 -> 53958 | I43: =I42-H42 -> 74532 | J43: =J42-I42 -> -77340 | R43: =R42-Q42 -> 155424 | S43: =S42-R42 -> 49325 | T43: =T42-S42 -> 35137 | U43: =U42-T42 -> 12433
B44: Cinema Hub | G44: 18040 | H44: 19990 | I44: 17946 | J44: 11256 | K44: =J44-I44 -> -6690 | R44: 13446 | S44: 16519 | T44: 13953 | U44: 11256 | V44: =U44-T44 -> -2697
B45: Net change | D45: =D44-C44 -> 0 | E45: =E44-D44 -> 0 | F45: =F44-E44 -> 0 | G45: =G44-F44 -> 18040 | H45: =H44-G44 -> 1950 | I45: =I44-H44 -> -2044 | J45: =J44-I44 -> -6690 | R45: =R44-Q44 -> 13446 | S45: =S44-R44 -> 3073 | T45: =T44-S44 -> -2566 | U45: =U44-T44 -> -2697
...

Sheet Projects Detail Flow
A1: Metrics | B1: 46048 | C1: 46054 | D1: 46082 | E1: 46113 | F1: 46143 | G1: 46174 | H1: 46204 | I1: 46235 | J1: 46266 | K1: 46296 | L1: 46327 | M1: 46357
A2: Page views (Actual) | F2: 3272867 | G2: 3407958 | H2: 3167821 | I2: 2489454
A3: Net change | G3: =G2-F2 -> 135091 | H3: =H2-G2 -> -240137 | I3: =I2-H2 -> -678367
A4: Growth Rate (%) | G4: =G2/F2-1 -> 0.041276043 | H4: =H2/G2-1 -> -0.070463603 | I4: =I2/H2-1 -> -0.2141431
A6: Page view by Project
A7: Cinema Hub | F7: 976664 | G7: 842352 | H7: 810565 | I7: 562237
A8: Phạt nguội | F8: 294668 | G8: 573611 | H8: 154889 | I8: 198174
A9: Home Page | F9: 236663 | G9: 193278 | H9: 195988 | I9: 150305
A10: Tiktok | F10: 210707 | G10: 237410 | H10: 227699 | I10: 138282
A11: Financial Hub | F11: =sum(F12:F22) -> 150769 | G11: =sum(G12:G22) -> 126976 | H11: =sum(H12:H22) -> 125336 | I11: =sum(I12:I22) -> 159027
A12: Vay Nhanh | F12: ='Financial Hub'!J6 -> 127284 | G12: ='Financial Hub'!K6 -> 76228 | H12: ='Financial Hub'!L6 -> 65899 | I12: ='Financial Hub'!M6 -> 84745
A13: Điểm Tín Dụng | F13: ='Financial Hub'!J14 -> 7894 | G13: ='Financial Hub'!K14 -> 8565 | H13: ='Financial Hub'!L14 -> 29368 | I13: ='Financial Hub'!M14 -> 55110
A14: Ví Trả Sau | F14: ='Financial Hub'!J22 -> 10134 | G14: ='Financial Hub'!K22 -> 37232 | H14: ='Financial Hub'!L22 -> 22949 | I14: ='Financial Hub'!M22 -> 14206
A15: Túi Thần Tài | F15: ='Financial Hub'!J30 -> 1131 | G15: ='Financial Hub'!K30 -> 1029 | H15: ='Financial Hub'!L30 -> 2339 | I15: ='Financial Hub'!M30 -> 1808
A16: Mở Thẻ Tín Dụng | F16: ='Financial Hub'!J38 -> 1634 | G16: ='Financial Hub'!K38 -> 1422 | H16: ='Financial Hub'!L38 -> 1629 | I16: ='Financial Hub'!M38 -> 1061
A17: Trả Góp Apple | F17: ='Financial Hub'!J45 -> 807 | G17: ='Financial Hub'!K45 -> 771 | H17: ='Financial Hub'!L45 -> 1167 | I17: ='Financial Hub'!M45 -> 794
A18: Chứng Khoán | F18: ='Financial Hub'!J52 -> 689 | G18: ='Financial Hub'!K52 -> 666 | H18: ='Financial Hub'!L52 -> 702 | I18: ='Financial Hub'!M52 -> 463
A19: Tiết Kiệm Online | F19: ='Financial Hub'!J60 -> 430 | G19: ='Financial Hub'!K60 -> 408 | H19: ='Financial Hub'!L60 -> 550 | I19: ='Financial Hub'!M60 -> 386
A20: Thanh Toán Thẻ Tín Dụng | F20: ='Financial Hub'!J67 -> 482 | G20: ='Financial Hub'!K67 -> 427 | H20: ='Financial Hub'!L67 -> 468 | I20: ='Financial Hub'!M67 -> 300
A21: Chứng Chỉ Quỹ | F21: ='Financial Hub'!J74 -> 256 | G21: ='Financial Hub'!K74 -> 206 | H21: ='Financial Hub'!L74 -> 237 | I21: ='Financial Hub'!M74 -> 137
A22: Sàn Đầu Tư | F22: ='Financial Hub'!J81 -> 28 | G22: ='Financial Hub'!K81 -> 22 | H22: ='Financial Hub'!L81 -> 28 | I22: ='Financial Hub'!M81 -> 17
A23: Game | F23: 57713 | G23: 36827 | H23: 57118 | I23: 31153
A24: Bảo hiểm ô tô | F24: 12014 | G24: 10943 | H24: 12417 | I24: 10465
A25: Bảo hiểm xe máy | F25: 4910 | G25: 3905 | H25: 5280 | I25: 5746
A26: Bảo hiểm y tế | F26: 6052 | G26: 14059 | H26: 30251 | I26: 7667
A27: Others | F27: 1321017 | G27: 1365943 | H27: 1545397 | I27: 1289591
A30: %Page view by Project = PV project / PV total
A31: %Home Page
A32: %Cinema Hub
A33: %Financial Hub
A34: %Tiktok
A35: %Phạt nguội
A36: %Game

Sheet Cinema Hub
A1: Project | B1: Update to: 23 | C1: 46143 | D1: 46174 | E1: 46204 | F1: 46235 | G1: VS. SPLM | I1: Full month | J1: 46143 | K1: 46174 | L1: 46204 | M1: 46235 | N1: VS. LM | O1: 46266 | P1: 46296 | Q1: 46327 | R1: 46357 | T1: %gap | U1: %growth
A2: Traffic (Page Views) | C2: =SUM(C6,C14,C22,C30,C38,C46) -> 754220 | D2: =SUM(D6,D14,D22,D30,D38,D46) -> 656241 | E2: =SUM(E6,E14,E22,E30,E38,E46) -> 605360 | F2: =SUM(F6,F14,F22,F30,F38,F46) -> 562237 | G2: =F2-E2 -> -43123 | J2: =SUM(J6,J14,J22,J30,J38,J46) -> 976664 | K2: =SUM(K6,K14,K22,K30,K38,K46) -> 842352 | L2: =SUM(L6,L14,L22,L30,L38,L46) -> 810565 | M2: =SUM(M6,M14,M22,M30,M38,M46) -> 562237 | N2: =M2-L2 -> -248328 | O2: =M2*(R2/M2)^(1/4) -> 718558.91 | P2: =M2*(R2/M2)^(2/4) -> 918343.89 | Q2: =M2*(R2/M2)^(3/4) -> 1173676.2 | R2: 1500000 | T2: =R2/SUM(L2:M2) -> 1.0926558 | U2: =T2^(1/4) -1 -> 0.022399996
A3: Net change | C3: =C2-0 -> 754220 | D3: =D2-C2 -> -97979 | E3: =E2-D2 -> -50881 | F3: =F2-E2 -> -43123 | J3: =J2-0 -> 976664 | K3: =K2-J2 -> -134312 | L3: =L2-K2 -> -31787 | M3: =M2-L2 -> -248328 | O3: =O2-M2 -> 156321.91 | P3: =P2-O2 -> 199784.98 | Q3: =Q2-P2 -> 255332.32 | R3: =R2-Q2 -> 326323.79
A4: Growth Rate (%) | D4: =(D2/C2)-1 -> -0.12990772 | E4: =(E2/D2)-1 -> -0.077534016 | F4: =(F2/E2)-1 -> -0.071235298 | G4: =F4-E4 -> 0.0062987177 | K4: =(K2/J2)-1 -> -0.13752119 | L4: =(L2/K2)-1 -> -0.037736006 | M4: =(M2/L2)-1 -> -0.30636408 | N4: =M4-L4 -> -0.26862807 | O4: =O2/M2-1 -> 0.27803562 | P4: =P2/O2-1 -> 0.27803562 | Q4: =Q2/P2-1 -> 0.27803562 | R4: =R2/Q2-1 -> 0.27803562 | S4: Target = A
S5: %Gap = Target / Recent
A6: Cinema_Rạp Phim | C6: 274505 | D6: 314369 | E6: 303374 | F6: 290123 | G6: =F6-E6 -> -13251 | J6: 374701 | K6: 400451 | L6: 412039 | M6: 290123 | N6: =M6-L6 -> -121916 | S6: %Growth = [(%Gap)^(1/month)] - 1
A7: Market: 4.203.090 | B7: Organic | C7: 257816 | D7: 297712 | E7: 288524 | F7: 267614 | G7: =F7-E7 -> -20910 | J7: 352702 | K7: 379527 | L7: 389838 | M7: 267614 | N7: =M7-L7 -> -122224 | S7: Forecast_t+1 = t * (1 + %Growth)
A8: =IFERROR(__xludf.DUMMYFUNCTION("F6 / VALUE(REGEXREPLACE(A7, ""[^0-9]"", """"))"),0.0690261212584075) -> 0.069026121 | B8: Direct | C8: 9515 | D8: 10869 | E8: 11424 | F8: 10576 | G8: =F8-E8 -> -848 | J8: 12886 | K8: 13805 | L8: 15061 | M8: 10576 | N8: =M8-L8 -> -4485
B9: Referral | C9: 2741 | D9: 3319 | E9: 2994 | F9: 2918 | G9: =F9-E9 -> -76 | J9: 3765 | K9: 4136 | L9: 4127 | M9: 2918 | N9: =M9-L9 -> -1209
B10: Paid | C10: 77 | D10: 110 | E10: 38 | F10: 8165 | G10: =F10-E10 -> 8127 | J10: 118 | K10: 127 | L10: 2253 | M10: 8165 | N10: =M10-L10 -> 5912
B11: Others | C11: 4356 | D11: 2359 | E11: 394 | F11: 274 | G11: =F11-E11 -> -120 | J11: 5230 | K11: 2856 | L11: 641 | M11: 274 | N11: =M11-L11 -> -367
B12: Cross | F12: 576 | G12: =F12-E12 -> 576 | L12: 119 | M12: 576 | N12: =M12-L12 -> 457
A14: Cinema_Phim Chi Tiết | C14: 411911 | D14: 274170 | E14: 236009 | F14: 213241 | G14: =F14-E14 -> -22768 | J14: 507256 | K14: 353136 | L14: 309907 | M14: 213241 | N14: =M14-L14 -> -96666
A15: Market: 1.743.000 | B15: Organic | C15: 224461 | D15: 206660 | E15: 193782 | F15: 180270 | G15: =F15-E15 -> -13512 | J15: 293345 | K15: 269361 | L15: 256968 | M15: 180270 | N15: =M15-L15 -> -76698
A16: =IFERROR(__xludf.DUMMYFUNCTION("F14 / VALUE(REGEXREPLACE(A15, ""[^0-9]"", """"))"),0.12234136546184739) -> 0.12234137 | B16: Direct | C16: 172910 | D16: 30436 | E16: 31835 | F16: 22398 | G16: =F16-E16 -> -9437 | J16: 195502 | K16: 44159 | L16: 39230 | M16: 22398 | N16: =M16-L16 -> -16832
B17: Paid | C17: 803 | D17: 24191 | E17: 2058 | F17: 4383 | G17: =F17-E17 -> 2325 | J17: 9588 | K17: 11405 | L17: 9283 | M17: 5457 | N17: =M17-L17 -> -3826
B18: Referral | C18: 7249 | D18: 9697 | E18: 7634 | F18: 5457 | G18: =F18-E18 -> -2177 | J18: 1205 | K18: 24267 | L18: 3401 | M18: 4383 | N18: =M18-L18 -> 982
B19: Others | C19: 6488 | D19: 3186 | E19: 700 | F19: 506 | G19: =F19-E19 -> -194 | J19: 7614 | K19: 3940 | L19: 969 | M19: 506 | N19: =M19-L19 -> -463
B20: Cross | F20: 227 | G20: =F20-E20 -> 227 | J20: 2 | K20: 4 | L20: 56 | M20: 227 | N20: =M20-L20 -> 171
A22: Cinema_Blog | C22: 40744 | D22: 37560 | E22: 33085 | F22: 30620 | G22: =F22-E22 -> -2465 | J22: 58517 | K22: 49895 | L22: 45055 | M22: 30620 | N22: =M22-L22 -> -14435
A23: Market: 3.142.000 | B23: Organic | C23: 35616 | D23: 32681 | E23: 28496 | F23: 25835 | G23: =F23-E23 -> -2661 | J23: 51261 | K23: 43724 | L23: 38629 | M23: 25835 | N23: =M23-L23 -> -12794
A24: =IFERROR(__xludf.DUMMYFUNCTION("F22 / VALUE(REGEXREPLACE(A23, ""[^0-9]"", """"))"),0.009745385105028644) -> 0.0097453851 | B24: Referral | C24: 2500 | D24: 2428 | E24: 2408 | F24: 2113 | G24: =F24-E24 -> -295 | J24: 3561 | K24: 2944 | L24: 3054 | M24: 2587 | N24: =M24-L24 -> -467
B25: Direct | C25: 2366 | D25: 2341 | E25: 2146 | F25: 2587 | G25: =F25-E25 -> 441 | J25: 3391 | K25: 3100 | L25: 3293 | M25: 2113 | N25: =M25-L25 -> -1180
B26: Others | C26: 250 | D26: 100 | E26: 34 | F26: 52 | G26: =F26-E26 -> 18 | J26: 291 | K26: 117 | L26: 54 | M26: 52 | N26: =M26-L26 -> -2
B27: Paid | C27: 12 | D27: 10 | E27: 1 | F27: 32 | G27: =F27-E27 -> 31 | J27: 13 | K27: 10 | L27: 25 | M27: 32 | N27: =M27-L27 -> 7
B28: Cross | F28: 1 | G28: =F28-E28 -> 1 | M28: 1 | N28: =M28-L28 -> 1
A30: Cinema_Lịch Chiếu | C30: 25100 | D30: 27532 | E30: 29611 | F30: 25842 | G30: =F30-E30 -> -3769 | J30: 33650 | K30: 35527 | L30: 38994 | M30: 25842 | N30: =M30-L30 -> -13152
A31: Market: 160.000 | B31: Organic | C31: 20376 | D31: 22910 | E31: 25255 | F31: 19930 | G31: =F31-E31 -> -5325 | J31: 27516 | K31: 29603 | L31: 32885 | M31: 19930 | N31: =M31-L31 -> -12955
A32: =IFERROR(__xludf.DUMMYFUNCTION("F30 / VALUE(REGEXREPLACE(A31, ""[^0-9]"", """"))"),0.1615125) -> 0.1615125 | B32: Direct | C32: 2704 | D32: 2851 | E32: 3377 | F32: 3472 | G32: =F32-E32 -> 95 | J32: 3531 | K32: 3726 | L32: 4467 | M32: 3472 | N32: =M32-L32 -> -995
B33: Referral | C33: 759 | D33: 959 | E33: 749 | F33: 686 | G33: =F33-E33 -> -63 | J33: 1061 | K33: 1180 | L33: 1002 | M33: 686 | N33: =M33-L33 -> -316
B34: Others | C34: 1195 | D34: 693 | E34: 207 | F34: 175 | G34: =F34-E34 -> -32 | J34: 1453 | K34: 841 | L34: 272 | M34: 175 | N34: =M34-L34 -> -97
B35: Paid | C35: 66 | D35: 119 | E35: 23 | F35: 1559 | G35: =F35-E35 -> 1536 | J35: 89 | K35: 176 | L35: 360 | M35: 1559 | N35: =M35-L35 -> 1199
B36: Cross | F36: 20 | G36: =F36-E36 -> 20 | K36: 1 | L36: 8 | M36: 20 | N36: =M36-L36 -> 12
A38: Cinema_News | C38: 1862 | D38: 2417 | E38: 3221 | F38: 2332 | G38: =F38-E38 -> -889 | J38: 2395 | K38: 3121 | L38: 4485 | M38: 2332 | N38: =M38-L38 -> -2153
B39: Organic | C39: 1507 | D39: 2067 | E39: 2845 | F39: 2067 | G39: =F39-E39 -> -778 | J39: 1969 | K39: 2670 | L39: 3941 | M39: 2067 | N39: =M39-L39 -> -1874
B40: Direct | C40: 146 | D40: 218 | E40: 205 | F40: 146 | G40: =F40-E40 -> -59 | J40: 175 | K40: 261 | L40: 285 | M40: 146 | N40: =M40-L40 -> -139
B41: Referral | C41: 195 | D41: 114 | E41: 168 | F41: 80 | G41: =F41-E41 -> -88 | J41: 232 | K41: 167 | L41: 239 | M41: 80 | N41: =M41-L41 -> -159
B42: Others | C42: 14 | D42: 17 | E42: 3 | F42: 13 | G42: =F42-E42 -> 10 | J42: 19 | K42: 21 | L42: 3 | M42: 13 | N42: =M42-L42 -> 10
B43: Paid | D43: 1 | F43: 23 | G43: =F43-E43 -> 23 | K43: 2 | L43: 17 | M43: 23 | N43: =M43-L43 -> 6
B44: Cross | F44: 3 | G44: =F44-E44 -> 3 | M44: 3 | N44: =M44-L44 -> 3
...

Sheet Financial Hub
A1: Project | C1: 46143 | D1: 46174 | E1: 46204 | F1: 46235 | G1: VS. SPLM | I1: Project | J1: 46143 | K1: 46174 | L1: 46204 | M1: 46235 | N1: VS. LM
A2: Traffic (Page Views) | C2: =SUM(C6,C14,C22,C30,C38,C45,C52,C60,C67,C74,C81) -> 112968 | D2: =SUM(D6,D14,D22,D30,D38,D45,D52,D60,D67,D74,D81) -> 96671 | E2: =SUM(E6,E14,E22,E30,E38,E45,E52,E60,E67,E74,E81) -> 75685 | F2: =SUM(F6,F14,F22,F30,F38,F45,F52,F60,F67,F74,F81) -> 159646 | G2: =F2-E2 -> 83961 | J2: =SUM(J6,J14,J22,J30,J38,J45,J52,J60,J67,J74,J81) -> 150769 | K2: =SUM(K6,K14,K22,K30,K38,K45,K52,K60,K67,K74,K81) -> 126976 | L2: =SUM(L6,L14,L22,L30,L38,L45,L52,L60,L67,L74,L81) -> 125336 | M2: =SUM(M6,M14,M22,M30,M38,M45,M52,M60,M67,M74,M81) -> 159027 | N2: =M2-L2 -> 33691
A3: Net change | C3: =C2-0 -> 112968 | D3: =D2-C2 -> -16297 | E3: =E2-D2 -> -20986 | F3: =F2-E2 -> 83961 | J3: =J2-0 -> 150769 | K3: =K2-J2 -> -23793 | L3: =L2-K2 -> -1640 | M3: =M2-L2 -> 33691
A4: Growth Rate (%) | D4: =(D2/C2)-1 -> -0.14426209 | E4: =(E2/D2)-1 -> -0.21708682 | F4: =(F2/E2)-1 -> 1.109348 | G4: =F4-E4 -> 1.3264348 | K4: =K2/J2 -> 0.84218904 | L4: =L2/K2 -> 0.98708417 | M4: =M2/L2 -> 1.2688055 | N4: =M4-L4 -> 0.28172128
A6: Vay Nhanh | C6: 95156 | D6: 56053 | E6: 38969 | F6: 84745 | G6: =F6-E6 -> 45776 | J6: =sum(J7:J12) -> 127284 | K6: =sum(K7:K12) -> 76228 | L6: =sum(L7:L12) -> 65899 | M6: =sum(M7:M12) -> 84745 | N6: =M6-L6 -> 18846
A7: Market: 2,132,450 | B7: Organic | C7: 21355 | D7: 20370 | E7: 32285 | F7: 30442 | G7: =F7-E7 -> -1843 | J7: 28291 | K7: 27672 | L7: 42141 | M7: 30442 | N7: =M7-L7 -> -11699
A8: =IFERROR(__xludf.DUMMYFUNCTION("F6 / VALUE(REGEXREPLACE(A7, ""[^0-9]"", """"))"),0.039740673872775446) -> 0.039740674 | B8: Paid | C8: 67175 | D8: 30238 | E8: 567 | F8: 1164 | G8: =F8-E8 -> 597 | J8: 90449 | K8: 41503 | L8: 898 | M8: 1164 | N8: =M8-L8 -> 266
B9: Referral | C9: 2829 | D9: 2929 | E9: 4071 | F9: 48526 | G9: =F9-E9 -> 44455 | J9: 3718 | K9: 3715 | L9: 19282 | M9: 48526 | N9: =M9-L9 -> 29244
B10: Direct | C10: 1661 | D10: 1693 | E10: 1615 | F10: 3113 | G10: =F10-E10 -> 1498 | J10: 2177 | K10: 2224 | L10: 2646 | M10: 3113 | N10: =M10-L10 -> 467
B11: Others | C11: 998 | D11: 362 | E11: 425 | F11: 1471 | G11: =F11-E11 -> 1046 | J11: 1169 | K11: 451 | L11: 920 | M11: 1471 | N11: =M11-L11 -> 551
B12: Cross | C12: 1138 | D12: 461 | E12: 6 | F12: 29 | G12: =F12-E12 -> 23 | J12: 1480 | K12: 663 | L12: 12 | M12: 29 | N12: =M12-L12 -> 17
A14: Điểm Tín Dụng | C14: 6106 | D14: 6491 | E14: 12623 | F14: 55306 | G14: =F14-E14 -> 42683 | J14: =sum(J15:J18) -> 7894 | K14: =sum(K15:K18) -> 8565 | L14: =sum(L15:L18) -> 29368 | M14: =sum(M15:M18) -> 55110 | N14: =M14-L14 -> 25742
A15: Market: 339.000 | B15: Paid | C15: 19 | D15: 24 | E15: 5062 | F15: 50615 | G15: =F15-E15 -> 45553 | J15: 23 | K15: 29 | L15: 20462 | M15: 50615 | N15: =M15-L15 -> 30153
A16: =IFERROR(__xludf.DUMMYFUNCTION("F14 / VALUE(REGEXREPLACE(A15, ""[^0-9]"", """"))"),0.16314454277286136) -> 0.16314454 | B16: Organic | C16: 5790 | D16: 6018 | E16: 6958 | F16: 3075 | G16: =F16-E16 -> -3883 | J16: 7669 | K16: 8144 | L16: 8049 | M16: 3075 | N16: =M16-L16 -> -4974
B17: Cross | D17: 1 | E17: 132 | F17: 1149 | G17: =F17-E17 -> 1017 | K17: 1 | L17: 503 | M17: 1149 | N17: =M17-L17 -> 646
B18: Direct | C18: 160 | D18: 321 | E18: 238 | F18: 271 | G18: =F18-E18 -> 33 | J18: 202 | K18: 391 | L18: 354 | M18: 271 | N18: =M18-L18 -> -83
B19: Referral | C19: 77 | D19: 112 | E19: 147 | F19: 143 | G19: =F19-E19 -> -4 | J19: 111 | K19: 142 | L19: 210 | M19: 143 | N19: =M19-L19 -> -67
B20: Others | C20: 60 | D20: 15 | E20: 86 | F20: 53 | G20: =F20-E20 -> -33 | J20: 65 | K20: 15 | L20: 127 | M20: 53 | N20: =M20-L20 -> -74
A22: Ví Trả Sau | C22: 7455 | D22: 30319 | E22: 18617 | F22: 14601 | G22: =F22-E22 -> -4016 | J22: =sum(J23:J26) -> 10134 | K22: =sum(K23:K26) -> 37232 | L22: =sum(L23:L26) -> 22949 | M22: =sum(M23:M26) -> 14206 | N22: =M22-L22 -> -8743
A23: Market: 609,990 | B23: Paid | C23: 577 | D23: 22382 | E23: 9034 | F23: 5262 | G23: =F23-E23 -> -3772 | J23: 725 | K23: 27365 | L23: 10418 | M23: 5262 | N23: =M23-L23 -> -5156
A24: =IFERROR(__xludf.DUMMYFUNCTION("F22 / VALUE(REGEXREPLACE(A23, ""[^0-9]"", """"))"),0.023936457974720896) -> 0.023936458 | B24: Organic | C24: 4807 | D24: 4996 | E24: 6063 | F24: 5869 | G24: =F24-E24 -> -194 | J24: 6736 | K24: 6770 | L24: 8317 | M24: 5869 | N24: =M24-L24 -> -2448
B25: Referral | C25: 1084 | D25: 1395 | E25: 2104 | F25: 1979 | G25: =F25-E25 -> -125 | J25: 1634 | K25: 1904 | L25: 3012 | M25: 1979 | N25: =M25-L25 -> -1033
B26: Direct | C26: 775 | D26: 907 | E26: 927 | F26: 1096 | G26: =F26-E26 -> 169 | J26: 1039 | K26: 1193 | L26: 1202 | M26: 1096 | N26: =M26-L26 -> -106
B27: Cross | C27: 48 | D27: 406 | E27: 299 | F27: 135 | G27: =F27-E27 -> -164 | J27: 247 | K27: 292 | L27: 297 | M27: 260 | N27: =M27-L27 -> -37
B28: Others | C28: 164 | D28: 233 | E28: 190 | F28: 260 | G28: =F28-E28 -> 70 | J28: 59 | K28: 529 | L28: 336 | M28: 135 | N28: =M28-L28 -> -201
A30: Túi Thần Tài | C30: 864 | D30: 795 | E30: 1786 | F30: 1809 | G30: =F30-E30 -> 23 | J30: =sum(J31:J34) -> 1131 | K30: =sum(K31:K34) -> 1029 | L30: =sum(L31:L34) -> 2339 | M30: =sum(M31:M34) -> 1808 | N30: =M30-L30 -> -531
A31: Market: N/A | B31: Organic | C31: 720 | D31: 663 | E31: 1556 | F31: 1505 | G31: =F31-E31 -> -51 | J31: 958 | K31: 864 | L31: 2022 | M31: 1505 | N31: =M31-L31 -> -517
B32: Referral | C32: 82 | D32: 65 | E32: 131 | F32: 175 | G32: =F32-E32 -> 44 | J32: 98 | K32: 74 | L32: 170 | M32: 175 | N32: =M32-L32 -> 5
B33: Direct | C33: 50 | D33: 52 | E33: 95 | F33: 118 | G33: =F33-E33 -> 23 | J33: 68 | K33: 76 | L33: 139 | M33: 118 | N33: =M33-L33 -> -21
B34: Others | C34: 6 | D34: 11 | E34: 3 | F34: 10 | G34: =F34-E34 -> 7 | J34: 7 | K34: 15 | L34: 8 | M34: 10 | N34: =M34-L34 -> 2
B35: Paid | C35: 6 | D35: 4 | E35: 1 | G35: =F35-E35 -> -1 | J35: 6 | K35: 5 | L35: 1 | N35: =M35-L35 -> -1
B36: Cross | F36: 1 | G36: =F36-E36 -> 1 | M36: 1 | N36: =M36-L36 -> 1
A38: Mở Thẻ Tín Dụng | C38: 1248 | D38: 1085 | E38: 1254 | F38: 1064 | G38: =F38-E38 -> -190 | J38: =sum(J39:J42) -> 1634 | K38: =sum(K39:K42) -> 1422 | L38: =sum(L39:L42) -> 1629 | M38: =sum(M39:M42) -> 1061 | N38: =M38-L38 -> -568
A39: Market: <1,000 | B39: Organic | C39: 1130 | D39: 970 | E39: 1127 | F39: 918 | G39: =F39-E39 -> -209 | J39: 1493 | K39: 1273 | L39: 1467 | M39: 918 | N39: =M39-L39 -> -549
B40: Referral | C40: 64 | D40: 30 | E40: 52 | F40: 41 | G40: =F40-E40 -> -11 | J40: 85 | K40: 44 | L40: 72 | M40: 41 | N40: =M40-L40 -> -31
B41: Direct | C41: 48 | D41: 42 | E41: 36 | F41: 48 | G41: =F41-E41 -> 12 | J41: 52 | K41: 53 | L41: 54 | M41: 48 | N41: =M41-L41 -> -6
B42: Paid | C42: 3 | D42: 36 | E42: 25 | F42: 54 | G42: =F42-E42 -> 29 | J42: 4 | K42: 52 | L42: 36 | M42: 54 | N42: =M42-L42 -> 18
B43: Others | C43: 3 | D43: 7 | E43: 14 | F43: 3 | G43: =F43-E43 -> -11 | J43: 3 | K43: 7 | L43: 17 | M43: 3 | N43: =M43-L43 -> -14
A45: Trả Góp Apple | C45: 650 | D45: 580 | E45: 852 | F45: 800 | G45: =F45-E45 -> -52 | J45: =sum(J46:J49) -> 807 | K45: =sum(K46:K49) -> 771 | L45: =sum(L46:L49) -> 1167 | M45: =sum(M46:M49) -> 794 | N45: =M45-L45 -> -373
B46: Organic | C46: 592 | D46: 476 | E46: 762 | F46: 667 | G46: =F46-E46 -> -95 | J46: 741 | K46: 656 | L46: 1063 | M46: 667 | N46: =M46-L46 -> -396
...

Sheet Structure
G1: Structure này chỉ là ví dụ, team Web Platform có thể điều chỉnh logic/ định nghĩa, nhưng đây là bức tranh tổng thể, trước mắt focus vào đầu phễu (Mục 1) => Làm sao về 4M vào tháng 12/2026?
G5: Key Metrics | H5: Ý Nghĩa
G6: 1. Tổng Page Views | H6: Tổng lượt xem trang từ TẤT CẢ nguồn (Organic, Paid, Direct, Social, Others)
G7: 2. Net Add | H7: Lượng traffic mới thêm vào tháng này so với tháng trước. Chỉ báo efforts có working không
G8: 3. Growth Rate (%) | H8: Phần trăm tăng trưởng traffic tuần/tháng. Mục tiêu: >.... là healthy?
G9: 4. Source Breakdown (%) | H9: Bao nhiêu % traffic đến từ mỗi source (Chỉ báo channels nào strongest, có thể quy định tì lệ?)
G10: 5. Net Change per Source | H10: Traffic từ 1 source tăng/giảm so với tháng trước. Chỉ báo source nào growing/declining
G11: 6. Pages cho use case | H11: Team Web tạo pages (Staking, Swap, Portfolio,..). Mỗi page nhận traffic từ Organic, Paid, Social,... Có thể show page nào hot, nào cần optimize?
G13: SPLM (Same Period Last Month)
G14: Khái niệm | H14: So sánh tháng hiện tại với tuần/tháng cùng kì tháng trước
G15: Tại sao? | H15: Loại bỏ seasonal factors - tránh nhầm lẫn vì yếu tố mùa vụ
G16: FULL MONTH (Toàn bộ tháng)
G17: Ý nghĩa | H17: Nhìn toàn cảnh tháng đó - So sánh với target & tháng trước
G18: Metrics | H18: Total page views, Net add, Growth Rate, Source breakdown, vs Target, vs Previous Month
